Traceback (most recent call last):
  File "/nas1-nfs1/home/rsr200002/miniconda3/lib/python3.8/site-packages/huggingface_hub/utils/_errors.py", line 239, in hf_raise_for_status
    response.raise_for_status()
  File "/nas1-nfs1/home/rsr200002/miniconda3/lib/python3.8/site-packages/requests/models.py", line 943, in raise_for_status
    raise HTTPError(http_error_msg, response=self)
requests.exceptions.HTTPError: 401 Client Error: Unauthorized for url: https://huggingface.co/mircosoft/codebert-base/resolve/main/vocab.json

The above exception was the direct cause of the following exception:

Traceback (most recent call last):
  File "/nas1-nfs1/home/rsr200002/miniconda3/lib/python3.8/site-packages/transformers/utils/hub.py", line 409, in cached_file
    resolved_file = hf_hub_download(
  File "/nas1-nfs1/home/rsr200002/miniconda3/lib/python3.8/site-packages/huggingface_hub/utils/_validators.py", line 124, in _inner_fn
    return fn(*args, **kwargs)
  File "/nas1-nfs1/home/rsr200002/miniconda3/lib/python3.8/site-packages/huggingface_hub/file_download.py", line 1067, in hf_hub_download
    metadata = get_hf_file_metadata(
  File "/nas1-nfs1/home/rsr200002/miniconda3/lib/python3.8/site-packages/huggingface_hub/utils/_validators.py", line 124, in _inner_fn
    return fn(*args, **kwargs)
  File "/nas1-nfs1/home/rsr200002/miniconda3/lib/python3.8/site-packages/huggingface_hub/file_download.py", line 1376, in get_hf_file_metadata
    hf_raise_for_status(r)
  File "/nas1-nfs1/home/rsr200002/miniconda3/lib/python3.8/site-packages/huggingface_hub/utils/_errors.py", line 268, in hf_raise_for_status
    raise RepositoryNotFoundError(message, response) from e
huggingface_hub.utils._errors.RepositoryNotFoundError: 401 Client Error. (Request ID: Root=1-64d81478-1ea685620fe0bbec68359f8a)

Repository Not Found for url: https://huggingface.co/mircosoft/codebert-base/resolve/main/vocab.json.
Please make sure you specified the correct `repo_id` and `repo_type`.
If the repo is private, make sure you are authenticated.
Invalid username or password.

During handling of the above exception, another exception occurred:

Traceback (most recent call last):
  File "transformation.py", line 409, in <module>
    main()
  File "transformation.py", line 379, in main
    tokenizer = tokenizer_class.from_pretrained(args.tokenizer_name,
  File "/nas1-nfs1/home/rsr200002/miniconda3/lib/python3.8/site-packages/transformers/tokenization_utils_base.py", line 1760, in from_pretrained
    resolved_vocab_files[file_id] = cached_file(
  File "/nas1-nfs1/home/rsr200002/miniconda3/lib/python3.8/site-packages/transformers/utils/hub.py", line 424, in cached_file
    raise EnvironmentError(
OSError: mircosoft/codebert-base is not a local folder and is not a valid model identifier listed on 'https://huggingface.co/models'
If this is a private repository, make sure to pass a token having permission to this repo with `use_auth_token` or log in with `huggingface-cli login` and pass `use_auth_token=True`.
